2021-06-23 11:10:56,320 DEBUG    root            Loaded Command Group: ['gcloud', 'app']
2021-06-23 11:10:56,703 DEBUG    root            Loaded Command Group: ['gcloud', 'app', 'deploy']
2021-06-23 11:10:56,705 DEBUG    root            Running [gcloud.app.deploy] with arguments: []
2021-06-23 11:10:56,730 DEBUG    google.auth.transport.requests Making request: POST https://oauth2.googleapis.com/token
2021-06-23 11:10:56,744 DEBUG    urllib3.connectionpool Starting new HTTPS connection (1): oauth2.googleapis.com:443
2021-06-23 11:10:56,937 DEBUG    urllib3.connectionpool https://oauth2.googleapis.com:443 "POST /token HTTP/1.1" 200 None
2021-06-23 11:10:56,972 DEBUG    root            Loading runtimes experiment config from [gs://runtime-builders/experiments.yaml]
2021-06-23 11:10:57,004 INFO     root            Reading [<googlecloudsdk.api_lib.storage.storage_util.ObjectReference object at 0x1073b3ca0>]
2021-06-23 11:10:57,339 DEBUG    root            
Traceback (most recent call last):
  File "/Users/dazyhero/Downloads/google-cloud-sdk/lib/googlecloudsdk/api_lib/storage/storage_api.py", line 313, in ReadObject
    self.client.objects.Get(get_req, download=download)
  File "/Users/dazyhero/Downloads/google-cloud-sdk/lib/googlecloudsdk/third_party/apis/storage/v1/storage_v1_client.py", line 1079, in Get
    return self._RunMethod(
  File "/Users/dazyhero/Downloads/google-cloud-sdk/lib/third_party/apitools/base/py/base_api.py", line 715, in _RunMethod
    download.InitializeDownload(http_request, client=self.client)
  File "/Users/dazyhero/Downloads/google-cloud-sdk/lib/third_party/apitools/base/py/transfer.py", line 327, in InitializeDownload
    raise exceptions.HttpError.FromResponse(response)
apitools.base.py.exceptions.HttpNotFoundError: HttpError accessing <https://storage.googleapis.com/storage/v1/b/runtime-builders/o/experiments.yaml?alt=media>: response: <{'x-guploader-uploadid': 'ADPycdu0AbUhqHJyV6fydK4ANCz2uvPUlH3MII-ESzQE0xwNQmnWasDUFkE_agQUbNsIl4nrL15PzQG44zBTA8rzyzI', 'content-type': 'text/html; charset=UTF-8', 'date': 'Wed, 23 Jun 2021 08:10:57 GMT', 'vary': 'Origin, X-Origin', 'expires': 'Wed, 23 Jun 2021 08:10:57 GMT', 'cache-control': 'private, max-age=0', 'content-length': '49', 'server': 'UploadServer', 'alt-svc': 'h3=":443"; ma=2592000,h3-29=":443"; ma=2592000,h3-T051=":443"; ma=2592000,h3-Q050=":443"; ma=2592000,h3-Q046=":443"; ma=2592000,h3-Q043=":443"; ma=2592000,quic=":443"; ma=2592000; v="46,43"', 'status': '404'}>, content <No such object: runtime-builders/experiments.yaml>

During handling of the above exception, another exception occurred:

Traceback (most recent call last):
  File "/Users/dazyhero/Downloads/google-cloud-sdk/lib/googlecloudsdk/api_lib/app/runtime_builders.py", line 269, in _Read
    with contextlib.closing(storage_client.ReadObject(object_)) as f:
  File "/Users/dazyhero/Downloads/google-cloud-sdk/lib/googlecloudsdk/api_lib/storage/storage_api.py", line 315, in ReadObject
    raise exceptions.BadFileException(
googlecloudsdk.calliope.exceptions.BadFileException: Could not read [<googlecloudsdk.api_lib.storage.storage_util.ObjectReference object at 0x1073b3ca0>]. Please retry: HTTPError 404: No such object: runtime-builders/experiments.yaml
2021-06-23 11:10:57,352 DEBUG    root            Experiment config file could not be read. This error is informational, and does not cause a deployment to fail. Reason: Unable to read the runtimes experiment config: [gs://runtime-builders/experiments.yaml], error: Could not read [<googlecloudsdk.api_lib.storage.storage_util.ObjectReference object at 0x1073b3ca0>]. Please retry: HTTPError 404: No such object: runtime-builders/experiments.yaml
Traceback (most recent call last):
  File "/Users/dazyhero/Downloads/google-cloud-sdk/lib/googlecloudsdk/api_lib/storage/storage_api.py", line 313, in ReadObject
    self.client.objects.Get(get_req, download=download)
  File "/Users/dazyhero/Downloads/google-cloud-sdk/lib/googlecloudsdk/third_party/apis/storage/v1/storage_v1_client.py", line 1079, in Get
    return self._RunMethod(
  File "/Users/dazyhero/Downloads/google-cloud-sdk/lib/third_party/apitools/base/py/base_api.py", line 715, in _RunMethod
    download.InitializeDownload(http_request, client=self.client)
  File "/Users/dazyhero/Downloads/google-cloud-sdk/lib/third_party/apitools/base/py/transfer.py", line 327, in InitializeDownload
    raise exceptions.HttpError.FromResponse(response)
apitools.base.py.exceptions.HttpNotFoundError: HttpError accessing <https://storage.googleapis.com/storage/v1/b/runtime-builders/o/experiments.yaml?alt=media>: response: <{'x-guploader-uploadid': 'ADPycdu0AbUhqHJyV6fydK4ANCz2uvPUlH3MII-ESzQE0xwNQmnWasDUFkE_agQUbNsIl4nrL15PzQG44zBTA8rzyzI', 'content-type': 'text/html; charset=UTF-8', 'date': 'Wed, 23 Jun 2021 08:10:57 GMT', 'vary': 'Origin, X-Origin', 'expires': 'Wed, 23 Jun 2021 08:10:57 GMT', 'cache-control': 'private, max-age=0', 'content-length': '49', 'server': 'UploadServer', 'alt-svc': 'h3=":443"; ma=2592000,h3-29=":443"; ma=2592000,h3-T051=":443"; ma=2592000,h3-Q050=":443"; ma=2592000,h3-Q046=":443"; ma=2592000,h3-Q043=":443"; ma=2592000,quic=":443"; ma=2592000; v="46,43"', 'status': '404'}>, content <No such object: runtime-builders/experiments.yaml>

During handling of the above exception, another exception occurred:

Traceback (most recent call last):
  File "/Users/dazyhero/Downloads/google-cloud-sdk/lib/googlecloudsdk/api_lib/app/runtime_builders.py", line 269, in _Read
    with contextlib.closing(storage_client.ReadObject(object_)) as f:
  File "/Users/dazyhero/Downloads/google-cloud-sdk/lib/googlecloudsdk/api_lib/storage/storage_api.py", line 315, in ReadObject
    raise exceptions.BadFileException(
googlecloudsdk.calliope.exceptions.BadFileException: Could not read [<googlecloudsdk.api_lib.storage.storage_util.ObjectReference object at 0x1073b3ca0>]. Please retry: HTTPError 404: No such object: runtime-builders/experiments.yaml

During handling of the above exception, another exception occurred:

Traceback (most recent call last):
  File "/Users/dazyhero/Downloads/google-cloud-sdk/lib/googlecloudsdk/api_lib/app/runtime_builders.py", line 518, in LoadFromURI
    with _Read(uri) as f:
  File "/Library/Developer/CommandLineTools/Library/Frameworks/Python3.framework/Versions/3.8/lib/python3.8/contextlib.py", line 113, in __enter__
    return next(self.gen)
  File "/Users/dazyhero/Downloads/google-cloud-sdk/lib/googlecloudsdk/api_lib/app/runtime_builders.py", line 276, in _Read
    raise FileReadError(six.text_type(e))
googlecloudsdk.api_lib.app.runtime_builders.FileReadError: Could not read [<googlecloudsdk.api_lib.storage.storage_util.ObjectReference object at 0x1073b3ca0>]. Please retry: HTTPError 404: No such object: runtime-builders/experiments.yaml

During handling of the above exception, another exception occurred:

Traceback (most recent call last):
  File "/Users/dazyhero/Downloads/google-cloud-sdk/lib/surface/app/deploy.py", line 145, in _ServerSideExperimentEnabled
    experiment_config = runtime_builders.Experiments.LoadFromURI(
  File "/Users/dazyhero/Downloads/google-cloud-sdk/lib/googlecloudsdk/api_lib/app/runtime_builders.py", line 522, in LoadFromURI
    raise ExperimentsError(
googlecloudsdk.api_lib.app.runtime_builders.ExperimentsError: Unable to read the runtimes experiment config: [gs://runtime-builders/experiments.yaml], error: Could not read [<googlecloudsdk.api_lib.storage.storage_util.ObjectReference object at 0x1073b3ca0>]. Please retry: HTTPError 404: No such object: runtime-builders/experiments.yaml
2021-06-23 11:10:57,425 ERROR    root            An app.yaml (or appengine-web.xml) file is required to deploy this directory as an App Engine application. Create an app.yaml file using the directions at https://cloud.google.com/appengine/docs/flexible/python/configuring-your-app-with-app-yaml (App Engine flexible environment) or https://cloud.google.com/appengine/docs/standard/python/config/appref (App Engine standard environment) under the tab for your language.
2021-06-23 11:10:57,425 DEBUG    root            (gcloud.app.deploy) [/Users/dazyhero/Development/it-hub] could not be identified as a valid source directory or file.
Traceback (most recent call last):
  File "/Users/dazyhero/Downloads/google-cloud-sdk/lib/googlecloudsdk/calliope/cli.py", line 982, in Execute
    resources = calliope_command.Run(cli=self, args=args)
  File "/Users/dazyhero/Downloads/google-cloud-sdk/lib/googlecloudsdk/calliope/backend.py", line 809, in Run
    resources = command_instance.Run(args)
  File "/Users/dazyhero/Downloads/google-cloud-sdk/lib/surface/app/deploy.py", line 123, in Run
    return deploy_util.RunDeploy(
  File "/Users/dazyhero/Downloads/google-cloud-sdk/lib/googlecloudsdk/command_lib/app/deploy_util.py", line 617, in RunDeploy
    services, configs = deployables.GetDeployables(
  File "/Users/dazyhero/Downloads/google-cloud-sdk/lib/googlecloudsdk/command_lib/app/deployables.py", line 491, in GetDeployables
    raise exceptions.UnknownSourceError(path)
googlecloudsdk.command_lib.app.exceptions.UnknownSourceError: [/Users/dazyhero/Development/it-hub] could not be identified as a valid source directory or file.
2021-06-23 11:10:57,434 ERROR    root            (gcloud.app.deploy) [/Users/dazyhero/Development/it-hub] could not be identified as a valid source directory or file.
